<?xml version="1.0" ?>

<sdf version="1.5">

  <world name="default">
  
    <!-- 地板-->  
    <include>
      <uri>model://ground_plane</uri>
    </include>

    <!-- 光線-->
    <include>
      <uri>model://sun</uri>
    </include>
    
    <model name="carcar">
    
      <link name="body_link">
        <pose>0 0 0 0 0 0</pose>
        
        <visual name="body_visual">
          <geometry>
            <box>
              <size>.4 .2 .1</size>
            </box>
          </geometry>
        </visual>
        
        <collision name="body_collision">
          <geometry>
            <box>
              <size>.4 .2 .1</size>
            </box>
          </geometry>
        </collision>
        
        <inertial>
          <inertia>
            <ixx>1</ixx>
            <ixy>0</ixy>
            <ixz>0</ixz>
            <iyy>1</iyy>
            <iyz>0</iyz>
            <izz>1</izz>
          </inertia>
          <mass>10</mass>
        </inertial>
        
      </link>
      
      <link name="left_wheel_link">
        <pose>0.2 0.1 0 1.57079632679 0 0</pose>
        <visual name="left_wheel_visual">          
          <geometry>
            <cylinder>
              <radius>0.1</radius>
              <length>0.1</length>
            </cylinder>
          </geometry>
        </visual>
        <collision name="left_wheel_collision">          
          <geometry>
            <cylinder>
              <radius>0.1</radius>
              <length>0.1</length>
            </cylinder>
          </geometry>
          
          <surface>
            <friction>
              <ode>
                <mu>1.0</mu>
                <mu2>1.0</mu2>
              </ode>
            </friction>
          </surface>
        </collision> 
        
       
        
        <inertial>
          <inertia>
            <ixx>0</ixx>
            <ixy>0</ixy>
            <ixz>0</ixz>
            <iyy>1</iyy>
            <iyz>0</iyz>
            <izz>0</izz>
          </inertia>
          <mass>10</mass>
        </inertial>
      </link>
      
      <link name="right_wheel_link">
        <pose>0.2 -0.1 0 1.57079632679 0 0</pose>
        <visual name="right_wheel_visual">          
          <geometry>
            <cylinder>
              <radius>0.1</radius>
              <length>0.1</length>
            </cylinder>
          </geometry>
        </visual>
        <collision name="right_wheel_collision">          
          <geometry>
            <cylinder>
              <radius>0.1</radius>
              <length>0.1</length>
            </cylinder>
          </geometry>
          
          <surface>
            <friction>
              <ode>
                <mu>1.0</mu>
                <mu2>1.0</mu2>
              </ode>
            </friction>
          </surface>
        </collision>               
        
        <inertial>
          <inertia>
            <ixx>0</ixx>
            <ixy>0</ixy>
            <ixz>0</ixz>
            <iyy>1</iyy>
            <iyz>0</iyz>
            <izz>0</izz>
          </inertia>
          <mass>10</mass>
        </inertial>
      </link>
      
      <joint name="robot_car_left_wheel_joint" type="revolute">
        <pose>0 0 0 0 0 0</pose>
        <axis>
          <xyz>0 0 1</xyz>        
        </axis>                
        <child>left_wheel_link</child>
        <parent>body_link</parent>
      </joint>
      
      <joint name="robot_car_right_wheel_joint" type="revolute">
        <pose>0 0 0 0 0 0</pose>
        <axis>
          <xyz>0 0 1</xyz>        
        </axis>        
        
        <child>right_wheel_link</child>
        <parent>body_link</parent>
      </joint> 
      
      <link name="left_wheel_back_link">
        <pose>-0.2 0.1 0 1.57079632679 0 0</pose>
        <visual name="left_wheel_back_visual">          
          <geometry>
            <cylinder>
              <radius>0.1</radius>
              <length>0.1</length>
            </cylinder>
          </geometry>
        </visual>
        <collision name="left_wheel_back_collision">          
          <geometry>
            <cylinder>
              <radius>0.1</radius>
              <length>0.1</length>
            </cylinder>
          </geometry>
          
          
          <surface>
            <friction>
              <ode>
                <mu>1.0</mu>
                <mu2>1.0</mu2>
              </ode>
            </friction>
          </surface>
          
        </collision> 
        
        
        
        <inertial>
          <inertia>
            <ixx>0</ixx>
            <ixy>0</ixy>
            <ixz>0</ixz>
            <iyy>1</iyy>
            <iyz>0</iyz>
            <izz>0</izz>
          </inertia>
          <mass>10</mass>
        </inertial>
      </link>
      
      <link name="right_wheel_back_link">
        <pose>-0.2 -0.1 0 1.57079632679 0 0</pose>
        <visual name="right_wheel_back_visual">          
          <geometry>
            <cylinder>
              <radius>0.1</radius>
              <length>0.1</length>
            </cylinder>
          </geometry>
        </visual>
        <collision name="right_wheel_back_collision">          
          <geometry>
            <cylinder>
              <radius>0.1</radius>
              <length>0.1</length>
            </cylinder>
          </geometry>
          
          <surface>
            <friction>
              <ode>
                <mu>1.0</mu>
                <mu2>1.0</mu2>
              </ode>
            </friction>
          </surface>
        </collision>                
        
        <inertial>
          <inertia>
            <ixx>0</ixx>
            <ixy>0</ixy>
            <ixz>0</ixz>
            <iyy>1</iyy>
            <iyz>0</iyz>
            <izz>0</izz>
          </inertia>
          <mass>10</mass>
        </inertial>
      </link>
      
      <joint name="robot_car_left_wheel_back_joint" type="revolute">
        <pose>0 0 0 0 0 0</pose>
        <axis>
          <xyz>0 0 1</xyz>
        </axis>                
        <child>left_wheel_back_link</child>
        <parent>body_link</parent>
      </joint>
      
      <joint name="robot_car_right_wheel_back_joint" type="revolute">
        <pose>0 0 0 0 0 0</pose>
        <axis>
          <xyz>0 0 1</xyz>        
        </axis>        
        
        <child>right_wheel_back_link</child>
        <parent>body_link</parent>
      </joint> 
      
      
      
    </model>    
    
      
    
  </world>
</sdf>
